<?xml version="1.0" ?>
<robot name="rh6frh5520">
  <material name="white">
    <color rgba="1.0 1.0 1.0 1.0"/>
  </material>
  <link name="world"/>
  <link name="rh6frh5520_base">
    <visual>
      <material name="white"/>
      <origin rpy="0 0 0" xyz="0 0 0"/>
      <geometry>
        <mesh filename="package://melfa_description/meshes/rh6frh5520/base.STL"/>
      </geometry>
    </visual>
    <collision>
      <origin rpy="0 0 0" xyz="0 0 0"/>
      <geometry>
        <mesh filename="package://melfa_description/meshes/rh6frh5520/base.STL"/>
      </geometry>
    </collision>
  </link>
  <link name="rh6frh5520_no1arm">
    <visual>
      <material name="white"/>
      <origin rpy="0 0 0" xyz="0 0 0"/>
      <geometry>
        <mesh filename="package://melfa_description/meshes/rh6frh5520/no1arm.STL"/>
      </geometry>
    </visual>
    <collision>
      <origin rpy="0 0 0" xyz="0 0 0"/>
      <geometry>
        <mesh filename="package://melfa_description/meshes/rh6frh5520/no1arm.STL"/>
      </geometry>
    </collision>
  </link>
  <link name="rh6frh5520_no2arm">
    <visual>
      <material name="white"/>
      <origin rpy="0 0 0" xyz="0 0 0"/>
      <geometry>
        <mesh filename="package://melfa_description/meshes/rh6frh5520/no2arm.STL"/>
      </geometry>
    </visual>
    <collision>
      <origin rpy="0 0 0" xyz="0 0 0"/>
      <geometry>
        <mesh filename="package://melfa_description/meshes/rh6frh5520/no2arm.STL"/>
      </geometry>
    </collision>
  </link>
  <link name="rh6frh5520_shaft_z"/>
  <link name="rh6frh5520_shaft">
    <visual>
      <material name="white"/>
      <origin rpy="0 0 0" xyz="0 0 0"/>
      <geometry>
        <mesh filename="package://melfa_description/meshes/rh6frh5520/shaft.STL"/>
      </geometry>
    </visual>
    <collision>
      <origin rpy="0 0 0" xyz="0 0 0"/>
      <geometry>
        <mesh filename="package://melfa_description/meshes/rh6frh5520/shaft.STL"/>
      </geometry>
    </collision>
  </link>
  <link name="rh6frh5520_default_tcp"/>
  <joint name="rh6frh5520_world_to_base" type="fixed">
    <origin rpy="0 0 0" xyz="0.0 0.0 0.0"/>
    <parent link="world"/>
    <child link="rh6frh5520_base"/>
  </joint>
  <joint name="rh6frh5520_joint_1" type="revolute">
    <origin rpy="0 0 0" xyz="0.0 0.0 0.0"/>
    <parent link="rh6frh5520_base"/>
    <child link="rh6frh5520_no1arm"/>
    <axis xyz="0 0 1"/>
    <limit effort="1" lower="-2.9670597283903604" upper="2.9670597283903604" velocity="6.981317007977318"/>
  </joint>
  <joint name="rh6frh5520_joint_2" type="revolute">
    <origin rpy="0 0 0" xyz="0.325 0.0 0.0"/>
    <parent link="rh6frh5520_no1arm"/>
    <child link="rh6frh5520_no2arm"/>
    <axis xyz="0 0 1"/>
    <limit effort="1" lower="-2.5307274153917776" upper="2.5307274153917776" velocity="11.693705988362007"/>
  </joint>
  <joint name="rh6frh5520_joint_3" type="prismatic">
    <origin rpy="0 0 0" xyz="0.225 0.0 0.0"/>
    <parent link="rh6frh5520_no2arm"/>
    <child link="rh6frh5520_shaft_z"/>
    <axis xyz="0 0 1"/>
    <limit effort="1" lower="0.133" upper="0.333" velocity="2.4"/>
  </joint>
  <joint name="rh6frh5520_joint_4" type="revolute">
    <origin rpy="0 0 0" xyz="0.0 0.0 0.0"/>
    <parent link="rh6frh5520_shaft_z"/>
    <child link="rh6frh5520_shaft"/>
    <axis xyz="0 0 1"/>
    <limit effort="1" lower="-6.283185307179586" upper="6.283185307179586" velocity="43.63323129985824"/>
  </joint>
  <joint name="rh6frh5520_shift_to_default_tcp" type="fixed">
    <origin rpy="0 0 0" xyz="0.0 0.0 0.0"/>
    <parent link="rh6frh5520_shaft"/>
    <child link="rh6frh5520_default_tcp"/>
  </joint>
</robot>
