<?xml version="1.0" ?>
<robot xmlns:xacro="http://www.ros.org/wiki/xacro">
    <xacro:macro name="rv4frl" params="parent prefix *origin">
        <material name="white">
            <color rgba="1.0 1.0 1.0 1.0"/>
        </material>
        <joint name="rv4frl_world_to_base" type="fixed">
            <origin rpy="0 0 0" xyz="0.0 0.0 0.0"/>
            <parent link="${parent}"/>
            <child link="rv4frl_base"/>
        </joint>
        <joint name="rv4frl_joint_1" type="revolute">
            <origin rpy="0 0 0" xyz="0.0 0.0 0.0"/>
            <parent link="rv4frl_base"/>
            <child link="rv4frl_shoulder"/>
            <axis xyz="0 0 1"/>
            <limit effort="1" lower="-4.1887902047863905" upper="4.1887902047863905" velocity="7.3303828583761845"/>
        </joint>
        <joint name="rv4frl_joint_2" type="revolute">
            <origin rpy="0 0 0" xyz="0.0 0.0 0.35"/>
            <parent link="rv4frl_shoulder"/>
            <child link="rv4frl_upper_arm"/>
            <axis xyz="0 1 0"/>
            <limit effort="1" lower="-2.0943951023931953" upper="2.0943951023931953" velocity="5.8643062867009474"/>
        </joint>
        <joint name="rv4frl_joint_3" type="revolute">
            <origin rpy="0 0 0" xyz="0.0 0.0 0.31"/>
            <parent link="rv4frl_upper_arm"/>
            <child link="rv4frl_elbow"/>
            <axis xyz="0 1 0"/>
            <limit effort="1" lower="0.0" upper="2.8623399732707" velocity="4.363323129985823"/>
        </joint>
        <joint name="rv4frl_joint_4" type="revolute">
            <origin rpy="0 0 0" xyz="-0.05 0.0 0.0"/>
            <parent link="rv4frl_elbow"/>
            <child link="rv4frl_forearm"/>
            <axis xyz="0 0 1"/>
            <limit effort="1" lower="-3.490658503988659" upper="3.490658503988659" velocity="9.42477796076938"/>
        </joint>
        <joint name="rv4frl_joint_5" type="revolute">
            <origin rpy="0 0 0" xyz="0.0 0.0 0.335"/>
            <parent link="rv4frl_forearm"/>
            <child link="rv4frl_wrist"/>
            <axis xyz="0 1 0"/>
            <limit effort="1" lower="-2.0943951023931953" upper="2.0943951023931953" velocity="10.873401239924673"/>
        </joint>
        <joint name="rv4frl_joint_6" type="revolute">
            <origin rpy="0 0 0" xyz="0.0 0.0 0.085"/>
            <parent link="rv4frl_wrist"/>
            <child link="rv4frl_hand_flange"/>
            <axis xyz="0 0 1"/>
            <limit effort="1" lower="-6.283185307179586" upper="6.283185307179586" velocity="12.566370614359172"/>
        </joint>
        <joint name="rv4frl_hand_tcp" type="fixed">
            <origin rpy="0 0 0" xyz="0.0 0.0 0.0"/>
            <parent link="rv4frl_hand_flange"/>
            <child link="rv4frl_default_tcp"/>
        </joint>
        <link name="rv4frl_base">
            <visual>
            <material name="white"/>
            <origin rpy="0 0 0" xyz="0 0 0"/>
            <geometry>
                <mesh filename="package://melfa_description/meshes/rv4frl/base.STL"/>
            </geometry>
            </visual>
            <collision>
            <origin rpy="0 0 0" xyz="0 0 0"/>
            <geometry>
                <mesh filename="package://melfa_description/meshes/rv4frl/base.STL"/>
            </geometry>
            </collision>
        </link>
        <link name="rv4frl_shoulder">
            <visual>
            <material name="white"/>
            <origin rpy="0 0 0" xyz="0 0 0"/>
            <geometry>
                <mesh filename="package://melfa_description/meshes/rv4frl/shoulder.STL"/>
            </geometry>
            </visual>
            <collision>
            <origin rpy="0 0 0" xyz="0 0 0"/>
            <geometry>
                <mesh filename="package://melfa_description/meshes/rv4frl/shoulder.STL"/>
            </geometry>
            </collision>
        </link>
        <link name="rv4frl_upper_arm">
            <visual>
            <material name="white"/>
            <origin rpy="0 0 0" xyz="0 0 0"/>
            <geometry>
                <mesh filename="package://melfa_description/meshes/rv4frl/upper_arm.STL"/>
            </geometry>
            </visual>
            <collision>
            <origin rpy="0 0 0" xyz="0 0 0"/>
            <geometry>
                <mesh filename="package://melfa_description/meshes/rv4frl/upper_arm.STL"/>
            </geometry>
            </collision>
        </link>
        <link name="rv4frl_elbow">
            <visual>
            <material name="white"/>
            <origin rpy="0 0 0" xyz="0 0 0"/>
            <geometry>
                <mesh filename="package://melfa_description/meshes/rv4frl/elbow.STL"/>
            </geometry>
            </visual>
            <collision>
            <origin rpy="0 0 0" xyz="0 0 0"/>
            <geometry>
                <mesh filename="package://melfa_description/meshes/rv4frl/elbow.STL"/>
            </geometry>
            </collision>
        </link>
        <link name="rv4frl_forearm">
            <visual>
            <material name="white"/>
            <origin rpy="0 0 0" xyz="0 0 0"/>
            <geometry>
                <mesh filename="package://melfa_description/meshes/rv4frl/forearm.STL"/>
            </geometry>
            </visual>
            <collision>
            <origin rpy="0 0 0" xyz="0 0 0"/>
            <geometry>
                <mesh filename="package://melfa_description/meshes/rv4frl/forearm.STL"/>
            </geometry>
            </collision>
        </link>
        <link name="rv4frl_wrist">
            <visual>
            <material name="white"/>
            <origin rpy="0 0 0" xyz="0 0 0"/>
            <geometry>
                <mesh filename="package://melfa_description/meshes/rv4frl/wrist.STL"/>
            </geometry>
            </visual>
            <collision>
            <origin rpy="0 0 0" xyz="0 0 0"/>
            <geometry>
                <mesh filename="package://melfa_description/meshes/rv4frl/wrist.STL"/>
            </geometry>
            </collision>
        </link>
        <link name="rv4frl_hand_flange">
            <visual>
            <material name="white"/>
            <origin rpy="0 0 0" xyz="0 0 0"/>
            <geometry>
                <mesh filename="package://melfa_description/meshes/rv4frl/hand_flange.STL"/>
            </geometry>
            </visual>
            <collision>
            <origin rpy="0 0 0" xyz="0 0 0"/>
            <geometry>
                <mesh filename="package://melfa_description/meshes/rv4frl/hand_flange.STL"/>
            </geometry>
            </collision>
        </link>
        <link name="rv4frl_default_tcp"/>
    </xacro:macro>
</robot>