<?xml version="1.0" ?>
<robot xmlns:xacro="http://www.ros.org/wiki/xacro">
    <xacro:macro name="rv2fr" params="parent prefix *origin">
        <material name="white">
            <color rgba="1.0 1.0 1.0 1.0"/>
        </material>
        <joint name="rv2fr_world_to_base" type="fixed">
            <origin rpy="0 0 0" xyz="0.0 0.0 0.0"/>
            <parent link="world"/>
            <child link="rv2fr_base"/>
        </joint>
        <joint name="rv2fr_joint_1" type="revolute">
            <origin rpy="0 0 0" xyz="0.0 0.0 0.0"/>
            <parent link="rv2fr_base"/>
            <child link="rv2fr_shoulder"/>
            <axis xyz="0 0 1"/>
            <limit effort="1" lower="-4.1887902047863905" upper="4.1887902047863905" velocity="5.235987755982989"/>
        </joint>
        <joint name="rv2fr_joint_2" type="revolute">
            <origin rpy="0 0 0" xyz="0.0 0.0 0.295"/>
            <parent link="rv2fr_shoulder"/>
            <child link="rv2fr_upper_arm"/>
            <axis xyz="0 1 0"/>
            <limit effort="1" lower="-2.0943951023931953" upper="2.0943951023931953" velocity="2.6179938779914944"/>
        </joint>
        <joint name="rv2fr_joint_3" type="revolute">
            <origin rpy="0 0 0" xyz="0.0 0.0 0.23"/>
            <parent link="rv2fr_upper_arm"/>
            <child link="rv2fr_elbow"/>
            <axis xyz="0 1 0"/>
            <limit effort="1" lower="0.0" upper="2.792526803190927" velocity="5.235987755982989"/>
        </joint>
        <joint name="rv2fr_joint_4" type="revolute">
            <origin rpy="0 0 0" xyz="-0.05 0.0 0.0"/>
            <parent link="rv2fr_elbow"/>
            <child link="rv2fr_forearm"/>
            <axis xyz="0 0 1"/>
            <limit effort="1" lower="-3.490658503988659" upper="3.490658503988659" velocity="7.853981633974483"/>
        </joint>
        <joint name="rv2fr_joint_5" type="revolute">
            <origin rpy="0 0 0" xyz="0.0 0.0 0.27"/>
            <parent link="rv2fr_forearm"/>
            <child link="rv2fr_wrist"/>
            <axis xyz="0 1 0"/>
            <limit effort="1" lower="-2.0943951023931953" upper="2.0943951023931953" velocity="7.853981633974483"/>
        </joint>
        <joint name="rv2fr_joint_6" type="revolute">
            <origin rpy="0 0 0" xyz="0.0 0.0 0.07"/>
            <parent link="rv2fr_wrist"/>
            <child link="rv2fr_hand_flange"/>
            <axis xyz="0 0 1"/>
            <limit effort="1" lower="-6.283185307179586" upper="6.283185307179586" velocity="12.566370614359172"/>
        </joint>
        <joint name="rv2fr_hand_tcp" type="fixed">
            <origin rpy="0 0 0" xyz="0.0 0.0 0.0"/>
            <parent link="rv2fr_hand_flange"/>
            <child link="rv2fr_default_tcp"/>
        </joint>
        <link name="rv2fr_base">
            <visual>
            <material name="white"/>
            <origin rpy="0 0 0" xyz="0 0 0"/>
            <geometry>
                <mesh filename="package://melfa_description/meshes/rv2fr/base.STL"/>
            </geometry>
            </visual>
            <collision>
            <origin rpy="0 0 0" xyz="0 0 0"/>
            <geometry>
                <mesh filename="package://melfa_description/meshes/rv2fr/base.STL"/>
            </geometry>
            </collision>
        </link>
        <link name="rv2fr_shoulder">
            <visual>
            <material name="white"/>
            <origin rpy="0 0 0" xyz="0 0 0"/>
            <geometry>
                <mesh filename="package://melfa_description/meshes/rv2fr/shoulder.STL"/>
            </geometry>
            </visual>
            <collision>
            <origin rpy="0 0 0" xyz="0 0 0"/>
            <geometry>
                <mesh filename="package://melfa_description/meshes/rv2fr/shoulder.STL"/>
            </geometry>
            </collision>
        </link>
        <link name="rv2fr_upper_arm">
            <visual>
            <material name="white"/>
            <origin rpy="0 0 0" xyz="0 0 0"/>
            <geometry>
                <mesh filename="package://melfa_description/meshes/rv2fr/upper_arm.STL"/>
            </geometry>
            </visual>
            <collision>
            <origin rpy="0 0 0" xyz="0 0 0"/>
            <geometry>
                <mesh filename="package://melfa_description/meshes/rv2fr/upper_arm.STL"/>
            </geometry>
            </collision>
        </link>
        <link name="rv2fr_elbow">
            <visual>
            <material name="white"/>
            <origin rpy="0 0 0" xyz="0 0 0"/>
            <geometry>
                <mesh filename="package://melfa_description/meshes/rv2fr/elbow.STL"/>
            </geometry>
            </visual>
            <collision>
            <origin rpy="0 0 0" xyz="0 0 0"/>
            <geometry>
                <mesh filename="package://melfa_description/meshes/rv2fr/elbow.STL"/>
            </geometry>
            </collision>
        </link>
        <link name="rv2fr_forearm">
            <visual>
            <material name="white"/>
            <origin rpy="0 0 0" xyz="0 0 0"/>
            <geometry>
                <mesh filename="package://melfa_description/meshes/rv2fr/forearm.STL"/>
            </geometry>
            </visual>
            <collision>
            <origin rpy="0 0 0" xyz="0 0 0"/>
            <geometry>
                <mesh filename="package://melfa_description/meshes/rv2fr/forearm.STL"/>
            </geometry>
            </collision>
        </link>
        <link name="rv2fr_wrist">
            <visual>
            <material name="white"/>
            <origin rpy="0 0 0" xyz="0 0 0"/>
            <geometry>
                <mesh filename="package://melfa_description/meshes/rv2fr/wrist.STL"/>
            </geometry>
            </visual>
            <collision>
            <origin rpy="0 0 0" xyz="0 0 0"/>
            <geometry>
                <mesh filename="package://melfa_description/meshes/rv2fr/wrist.STL"/>
            </geometry>
            </collision>
        </link>
        <link name="rv2fr_hand_flange">
            <visual>
            <material name="white"/>
            <origin rpy="0 0 0" xyz="0 0 0"/>
            <geometry>
                <mesh filename="package://melfa_description/meshes/rv2fr/hand_flange.STL"/>
            </geometry>
            </visual>
            <collision>
            <origin rpy="0 0 0" xyz="0 0 0"/>
            <geometry>
                <mesh filename="package://melfa_description/meshes/rv2fr/hand_flange.STL"/>
            </geometry>
            </collision>
        </link>
        <link name="rv2fr_default_tcp"/>
    </xacro:macro>
</robot>