<?xml version="1.0" ?>
<robot xmlns:xacro="http://www.ros.org/wiki/xacro">
    <xacro:macro name="cylinder_inertial" params="radius length mass *origin">
        <inertial>
        <mass value="${mass}" />
        <xacro:insert_block name="origin" />
        <inertia ixx="${0.0833333 * mass * (3 * radius * radius + length * length)}" ixy="0.0" ixz="0.0"
            iyy="${0.0833333 * mass * (3 * radius * radius + length * length)}" iyz="0.0"
            izz="${0.5 * mass * radius * radius}" />
        </inertial>
    </xacro:macro>
    <xacro:macro name="rv8crl" params="parent prefix *origin">
        <!-- Inertial parameters -->
        <xacro:property name="base_mass" value="0.4" />  <!-- These mass are INCORRRECT -->
        <xacro:property name="shoulder_mass" value="0.37000" />
        <xacro:property name="upper_arm_mass" value="0.83930" />
        <xacro:property name="elbow_mass" value="0.22750" />
        <xacro:property name="forearm_mass" value="0.12190" />
        <xacro:property name="wrist_mass" value="0.12190" />
        <xacro:property name="hand_flange_mass" value="0.01879" />

        <material name="white">
            <color rgba="1.0 1.0 1.0 1.0"/>
        </material>
        <joint name="${prefix}rv8crl_world_to_base" type="fixed">
            <origin xyz="0 0 0" rpy="0 -0 0" />
            <parent link="${parent}" />
            <child link="${prefix}rv8crl_base" />
            <dynamics damping="1.0" friction="1.0"/>
        </joint>
        <joint name="${prefix}rv8crl_joint_1" type="revolute">
            <origin rpy="0 0 0" xyz="0.0 0.0 0.0"/>
            <parent link="${prefix}rv8crl_base"/>
            <child link="${prefix}rv8crl_shoulder"/>
            <axis xyz="0 0 1"/>
            <limit effort="1" lower="-2.9670597283903604" upper="2.9670597283903604" velocity="5.026548245743669"/>
            <dynamics damping="1.0" friction="1.0"/>
        </joint>
        <joint name="${prefix}rv8crl_joint_2" type="revolute">
            <origin rpy="0 0 0" xyz="0.0 0.0 0.39"/>
            <parent link="${prefix}rv8crl_shoulder"/>
            <child link="${prefix}rv8crl_upper_arm"/>
            <axis xyz="0 1 0"/>
            <limit effort="1" lower="-1.9198621771937625" upper="1.9198621771937625" velocity="5.602506898901797"/>
            <dynamics damping="1.0" friction="1.0"/>
        </joint>
        <joint name="${prefix}rv8crl_joint_3" type="revolute">
            <origin rpy="0 0 0" xyz="0.0 0.0 0.45"/>
            <parent link="${prefix}rv8crl_upper_arm"/>
            <child link="${prefix}rv8crl_elbow"/>
            <axis xyz="0 1 0"/>
            <limit effort="1" lower="0.0" upper="2.8797932657906435" velocity="6.283185307179586"/>
            <dynamics damping="1.0" friction="1.0"/>
        </joint>
        <joint name="${prefix}rv8crl_joint_4" type="revolute">
            <origin rpy="0 0 0" xyz="-0.1 0.0 0.0"/>
            <parent link="${prefix}rv8crl_elbow"/>
            <child link="${prefix}rv8crl_forearm"/>
            <axis xyz="0 0 1"/>
            <limit effort="1" lower="-3.490658503988659" upper="3.490658503988659" velocity="5.88175957922089"/>
            <dynamics damping="1.0" friction="1.0"/>
        </joint>
        <joint name="${prefix}rv8crl_joint_5" type="revolute">
            <origin rpy="0 0 0" xyz="0.0 0.0 0.47"/>
            <parent link="${prefix}rv8crl_forearm"/>
            <child link="${prefix}rv8crl_wrist"/>
            <axis xyz="0 1 0"/>
            <limit effort="1" lower="-2.0943951023931953" upper="2.0943951023931953" velocity="7.853981633974483"/>
            <dynamics damping="1.0" friction="1.0"/>
        </joint>
        <joint name="${prefix}rv8crl_joint_6" type="revolute">
            <origin rpy="0 0 0" xyz="0.0 0.0 0.085"/>
            <parent link="${prefix}rv8crl_wrist"/>
            <child link="${prefix}rv8crl_hand_flange"/>
            <axis xyz="0 0 1"/>
            <limit effort="1" lower="-6.283185307179586" upper="6.283185307179586" velocity="12.566370614359172"/>
            <dynamics damping="1.0" friction="1.0"/>
        </joint>
        <joint name="${prefix}rv8crl_hand_tcp" type="fixed">
            <origin rpy="0 0 0" xyz="0.0 0.0 0.0"/>
            <parent link="${prefix}rv8crl_hand_flange"/>
            <child link="${prefix}rv8crl_default_tcp"/>
            <dynamics damping="1.0" friction="1.0"/>
        </joint>
        <link name="${prefix}rv8crl_base">
            <visual>
            <material name="white"/>
            <origin rpy="0 0 0" xyz="0 0 0"/>
            <geometry>
                <mesh filename="package://melfa_description/meshes/rv8crl/base.STL"/>
            </geometry>
            </visual>
            <collision>
            <origin rpy="0 0 0" xyz="0 0 0"/>
            <geometry>
                <mesh filename="package://melfa_description/meshes/rv8crl/base.STL"/>
            </geometry>
            </collision>
            <xacro:cylinder_inertial radius="0.06" length="0.05" mass="${base_mass}">
                <origin xyz="0.0 0.0 0.0" rpy="0 0 0" />
            </xacro:cylinder_inertial>
        </link>
        <link name="${prefix}rv8crl_shoulder">
            <visual>
            <material name="white"/>
            <origin rpy="0 0 0" xyz="0 0 0"/>
            <geometry>
                <mesh filename="package://melfa_description/meshes/rv8crl/shoulder.STL"/>
            </geometry>
            </visual>
            <collision>
            <origin rpy="0 0 0" xyz="0 0 0"/>
            <geometry>
                <mesh filename="package://melfa_description/meshes/rv8crl/shoulder.STL"/>
            </geometry>
            </collision>
            <xacro:cylinder_inertial radius="0.06" length="0.05" mass="${shoulder_mass}">
                <origin xyz="0.0 0.0 0.0" rpy="0 0 0" />
            </xacro:cylinder_inertial>
        </link>
        <link name="${prefix}rv8crl_upper_arm">
            <visual>
            <material name="white"/>
            <origin rpy="0 0 0" xyz="0 0 0"/>
            <geometry>
                <mesh filename="package://melfa_description/meshes/rv8crl/upper_arm.STL"/>
            </geometry>
            </visual>
            <collision>
            <origin rpy="0 0 0" xyz="0 0 0"/>
            <geometry>
                <mesh filename="package://melfa_description/meshes/rv8crl/upper_arm.STL"/>
            </geometry>
            </collision>
            <xacro:cylinder_inertial radius="0.06" length="0.05" mass="${upper_arm_mass}">
                <origin xyz="0.0 0.0 0.0" rpy="0 0 0" />
            </xacro:cylinder_inertial>
        </link>
        <link name="${prefix}rv8crl_elbow">
            <visual>
            <material name="white"/>
            <origin rpy="0 0 0" xyz="0 0 0"/>
            <geometry>
                <mesh filename="package://melfa_description/meshes/rv8crl/elbow.STL"/>
            </geometry>
            </visual>
            <collision>
            <origin rpy="0 0 0" xyz="0 0 0"/>
            <geometry>
                <mesh filename="package://melfa_description/meshes/rv8crl/elbow.STL"/>
            </geometry>
            </collision>
            <xacro:cylinder_inertial radius="0.06" length="0.05" mass="${elbow_mass}">
                <origin xyz="0.0 0.0 0.0" rpy="0 0 0" />
            </xacro:cylinder_inertial>
        </link>
        <link name="${prefix}rv8crl_forearm">
            <visual>
            <material name="white"/>
            <origin rpy="0 0 0" xyz="0 0 0"/>
            <geometry>
                <mesh filename="package://melfa_description/meshes/rv8crl/forearm.STL"/>
            </geometry>
            </visual>
            <collision>
            <origin rpy="0 0 0" xyz="0 0 0"/>
            <geometry>
                <mesh filename="package://melfa_description/meshes/rv8crl/forearm.STL"/>
            </geometry>
            </collision>
            <xacro:cylinder_inertial radius="0.06" length="0.05" mass="${forearm_mass}">
                <origin xyz="0.0 0.0 0.0" rpy="0 0 0" />
            </xacro:cylinder_inertial>
        </link>
        <link name="${prefix}rv8crl_wrist">
            <visual>
            <material name="white"/>
            <origin rpy="0 0 0" xyz="0 0 0"/>
            <geometry>
                <mesh filename="package://melfa_description/meshes/rv8crl/wrist.STL"/>
            </geometry>
            </visual>
            <collision>
            <origin rpy="0 0 0" xyz="0 0 0"/>
            <geometry>
                <mesh filename="package://melfa_description/meshes/rv8crl/wrist.STL"/>
            </geometry>
            </collision>
            <xacro:cylinder_inertial radius="0.06" length="0.05" mass="${wrist_mass}">
                <origin xyz="0.0 0.0 0.0" rpy="0 0 0" />
            </xacro:cylinder_inertial>
        </link>
        <link name="${prefix}rv8crl_hand_flange">
            <visual>
            <material name="white"/>
            <origin rpy="0 0 0" xyz="0 0 0"/>
            <geometry>
                <mesh filename="package://melfa_description/meshes/rv8crl/hand_flange.STL"/>
            </geometry>
            </visual>
            <collision>
            <origin rpy="0 0 0" xyz="0 0 0"/>
            <geometry>
                <mesh filename="package://melfa_description/meshes/rv8crl/hand_flange.STL"/>
            </geometry>
            </collision>
            <xacro:cylinder_inertial radius="0.06" length="0.05" mass="${hand_flange_mass}">
                <origin xyz="0.0 0.0 0.0" rpy="0 0 0" />
            </xacro:cylinder_inertial>
        </link>
        <link name="${prefix}rv8crl_default_tcp"/>
    </xacro:macro>
</robot>