<?xml version="1.0" ?>
<robot name="rv8crl">
  <material name="white">
    <color rgba="1.0 1.0 1.0 1.0"/>
  </material>
  <joint name="rv8crl_world_to_base" type="fixed">
    <origin rpy="0 0 0" xyz="0.0 0.0 0.0"/>
    <parent link="world"/>
    <child link="rv8crl_base"/>
  </joint>
  <joint name="rv8crl_joint_1" type="revolute">
    <origin rpy="0 0 0" xyz="0.0 0.0 0.0"/>
    <parent link="rv8crl_base"/>
    <child link="rv8crl_shoulder"/>
    <axis xyz="0 0 1"/>
    <limit effort="1" lower="-2.9670597283903604" upper="2.9670597283903604" velocity="5.026548245743669"/>
  </joint>
  <joint name="rv8crl_joint_2" type="revolute">
    <origin rpy="0 0 0" xyz="0.0 0.0 0.39"/>
    <parent link="rv8crl_shoulder"/>
    <child link="rv8crl_upper_arm"/>
    <axis xyz="0 1 0"/>
    <limit effort="1" lower="-1.9198621771937625" upper="1.9198621771937625" velocity="5.602506898901797"/>
  </joint>
  <joint name="rv8crl_joint_3" type="revolute">
    <origin rpy="0 0 0" xyz="0.0 0.0 0.45"/>
    <parent link="rv8crl_upper_arm"/>
    <child link="rv8crl_elbow"/>
    <axis xyz="0 1 0"/>
    <limit effort="1" lower="0.0" upper="2.8797932657906435" velocity="6.283185307179586"/>
  </joint>
  <joint name="rv8crl_joint_4" type="revolute">
    <origin rpy="0 0 0" xyz="-0.1 0.0 0.0"/>
    <parent link="rv8crl_elbow"/>
    <child link="rv8crl_forearm"/>
    <axis xyz="0 0 1"/>
    <limit effort="1" lower="-3.490658503988659" upper="3.490658503988659" velocity="5.88175957922089"/>
  </joint>
  <joint name="rv8crl_joint_5" type="revolute">
    <origin rpy="0 0 0" xyz="0.0 0.0 0.47"/>
    <parent link="rv8crl_forearm"/>
    <child link="rv8crl_wrist"/>
    <axis xyz="0 1 0"/>
    <limit effort="1" lower="-2.0943951023931953" upper="2.0943951023931953" velocity="7.853981633974483"/>
  </joint>
  <joint name="rv8crl_joint_6" type="revolute">
    <origin rpy="0 0 0" xyz="0.0 0.0 0.085"/>
    <parent link="rv8crl_wrist"/>
    <child link="rv8crl_hand_flange"/>
    <axis xyz="0 0 1"/>
    <limit effort="1" lower="-6.283185307179586" upper="6.283185307179586" velocity="12.566370614359172"/>
  </joint>
  <joint name="rv8crl_hand_tcp" type="fixed">
    <origin rpy="0 0 0" xyz="0.0 0.0 0.0"/>
    <parent link="rv8crl_hand_flange"/>
    <child link="rv8crl_default_tcp"/>
  </joint>
  <link name="world"/>
  <link name="rv8crl_base">
    <visual>
      <material name="white"/>
      <origin rpy="0 0 0" xyz="0 0 0"/>
      <geometry>
        <mesh filename="package://melfa_description/meshes/rv8crl/base.STL"/>
      </geometry>
    </visual>
    <collision>
      <origin rpy="0 0 0" xyz="0 0 0"/>
      <geometry>
        <mesh filename="package://melfa_description/meshes/rv8crl/base.STL"/>
      </geometry>
    </collision>
  </link>
  <link name="rv8crl_shoulder">
    <visual>
      <material name="white"/>
      <origin rpy="0 0 0" xyz="0 0 0"/>
      <geometry>
        <mesh filename="package://melfa_description/meshes/rv8crl/shoulder.STL"/>
      </geometry>
    </visual>
    <collision>
      <origin rpy="0 0 0" xyz="0 0 0"/>
      <geometry>
        <mesh filename="package://melfa_description/meshes/rv8crl/shoulder.STL"/>
      </geometry>
    </collision>
  </link>
  <link name="rv8crl_upper_arm">
    <visual>
      <material name="white"/>
      <origin rpy="0 0 0" xyz="0 0 0"/>
      <geometry>
        <mesh filename="package://melfa_description/meshes/rv8crl/upper_arm.STL"/>
      </geometry>
    </visual>
    <collision>
      <origin rpy="0 0 0" xyz="0 0 0"/>
      <geometry>
        <mesh filename="package://melfa_description/meshes/rv8crl/upper_arm.STL"/>
      </geometry>
    </collision>
  </link>
  <link name="rv8crl_elbow">
    <visual>
      <material name="white"/>
      <origin rpy="0 0 0" xyz="0 0 0"/>
      <geometry>
        <mesh filename="package://melfa_description/meshes/rv8crl/elbow.STL"/>
      </geometry>
    </visual>
    <collision>
      <origin rpy="0 0 0" xyz="0 0 0"/>
      <geometry>
        <mesh filename="package://melfa_description/meshes/rv8crl/elbow.STL"/>
      </geometry>
    </collision>
  </link>
  <link name="rv8crl_forearm">
    <visual>
      <material name="white"/>
      <origin rpy="0 0 0" xyz="0 0 0"/>
      <geometry>
        <mesh filename="package://melfa_description/meshes/rv8crl/forearm.STL"/>
      </geometry>
    </visual>
    <collision>
      <origin rpy="0 0 0" xyz="0 0 0"/>
      <geometry>
        <mesh filename="package://melfa_description/meshes/rv8crl/forearm.STL"/>
      </geometry>
    </collision>
  </link>
  <link name="rv8crl_wrist">
    <visual>
      <material name="white"/>
      <origin rpy="0 0 0" xyz="0 0 0"/>
      <geometry>
        <mesh filename="package://melfa_description/meshes/rv8crl/wrist.STL"/>
      </geometry>
    </visual>
    <collision>
      <origin rpy="0 0 0" xyz="0 0 0"/>
      <geometry>
        <mesh filename="package://melfa_description/meshes/rv8crl/wrist.STL"/>
      </geometry>
    </collision>
  </link>
  <link name="rv8crl_hand_flange">
    <visual>
      <material name="white"/>
      <origin rpy="0 0 0" xyz="0 0 0"/>
      <geometry>
        <mesh filename="package://melfa_description/meshes/rv8crl/hand_flange.STL"/>
      </geometry>
    </visual>
    <collision>
      <origin rpy="0 0 0" xyz="0 0 0"/>
      <geometry>
        <mesh filename="package://melfa_description/meshes/rv8crl/hand_flange.STL"/>
      </geometry>
    </collision>
  </link>
  <link name="rv8crl_default_tcp"/>
</robot>
