<?xml version="1.0" ?>
<robot xmlns:xacro="http://www.ros.org/wiki/xacro">
    <xacro:macro name="rv5as" params="parent prefix *origin">
        <material name="white">
            <color rgba="1.0 1.0 1.0 1.0"/>
        </material>
        <joint name="Mate1" type="fixed">
            <origin xyz="0 0 0" rpy="0 -0 0" />
            <parent link="${parent}" />
            <child link="rv5as_base" />
        </joint>
        <joint name="rv5as_hand_flange-to-default_tcp" type="fixed">
            <origin xyz="0 0 0" rpy="0 -0 0" />
            <parent link="rv5as_hand_flange" />
            <child link="rv5as_default_tcp" />
        </joint>
        <joint name="rv5as_joint_1" type="revolute">
            <axis xyz="0 0 1" />
            <limit effort="1" velocity="2.16421" lower="-4.18879" upper="4.18879" />
            <origin xyz="0 0 0" rpy="0 0 0" />       
            <parent link="rv5as_base" />
            <child link="rv5as_shoulder" />
        </joint>
        <joint name="rv5as_joint_2" type="revolute">
            <axis xyz="0 1 0" />
            <limit effort="1" velocity="2.16421" lower="-2.58309" upper="2.58309" />
            <origin xyz="0 0 0.254" rpy="0 0 0" />    
            <parent link="rv5as_shoulder" />
            <child link="rv5as_upper_arm" />
        </joint>
        <joint name="rv5as_joint_3" type="revolute">
            <axis xyz="0 1 0" />
            <limit effort="1" velocity="2.16421" lower="-2.61799" upper="2.61799" />
            <origin xyz="0 0 0.41" rpy="0 0 0" />
            <parent link="rv5as_upper_arm" />
            <child link="rv5as_elbow" />
        </joint>
        <joint name="rv5as_joint_4" type="revolute">
            <axis xyz="0 0 1" />
            <limit effort="1" velocity="3.4383" lower="-3.49066" upper="3.49066" />
            <origin xyz="0 0 0" rpy="0 0 0" />   
            <parent link="rv5as_elbow" />
            <child link="rv5as_forearm" />
        </joint>
        <joint name="rv5as_joint_5" type="revolute">
            <axis xyz="0 1 0" />
            <limit effort="1" velocity="6.21337" lower="-2.0944" upper="2.0944" />
            <origin xyz="0 0 0.5" rpy="0 0 0" />    
            <parent link="rv5as_forearm" />
            <child link="rv5as_wrist" />
        </joint>
        <joint name="rv5as_joint_6" type="revolute">
            <axis xyz="0 0 1" />
            <limit effort="1" velocity="6.28318" lower="-3.49066" upper="3.49066" />
            <origin xyz="0 0 0.125" rpy="0 0 0" /> 
            <parent link="rv5as_wrist" />
            <child link="rv5as_hand_flange" />
        </joint>
        <link name="rv5as_base">
            <visual>
                <material name="white"/>
                <geometry>
                    <mesh filename="package://melfa_description/meshes/rv5as/base.STL" />
                </geometry>
                <origin rpy="0.00 0.00 0.00" xyz="0.00 0.00 0.00"/>
            </visual>
            <collision>
                <geometry>
                    <mesh filename="package://melfa_description/meshes/rv5as/base.STL" />
                </geometry>
                <origin rpy="0.00 0.00 0.00" xyz="0.00 0.00 0.00"/>
            </collision>
        </link>
        <link name="rv5as_default_tcp" />
        <link name="rv5as_elbow">
            <visual>
                <material name="white"/>
                <geometry>
                    <mesh filename="package://melfa_description/meshes/rv5as/elbow.STL" />
                </geometry>
                <origin rpy="0.00 0.00 0.00" xyz="0.00 0.00 0.00"/>
            </visual>
            <collision>
                <geometry>
                    <mesh filename="package://melfa_description/meshes/rv5as/elbow.STL" />
                </geometry>
                <origin rpy="0.00 0.00 0.00" xyz="0.00 0.00 0.00"/>
            </collision>
        </link>
        <link name="rv5as_forearm">
            <visual>
                <material name="white"/>
                <geometry>
                    <mesh filename="package://melfa_description/meshes/rv5as/forearm.STL" />
                </geometry>
                <origin rpy="0.00 0.00 0.00" xyz="0.00 0.00 0.00"/>
            </visual>
            <collision>
                <geometry>
                    <mesh filename="package://melfa_description/meshes/rv5as/forearm.STL" />
                </geometry>
                <origin rpy="0.00 0.00 0.00" xyz="0.00 0.00 0.00"/>
            </collision>
        </link>
        <link name="rv5as_hand_flange">
            <visual>
                <material name="white"/>
                <geometry>
                    <mesh filename="package://melfa_description/meshes/rv5as/hand_flange.STL" />
                </geometry>
                <origin rpy="0.00 0.00 0.00" xyz="0.00 0.00 0.00"/>
            </visual>
            <collision>
                <geometry>
                    <mesh filename="package://melfa_description/meshes/rv5as/hand_flange.STL" />
                </geometry>
                <origin rpy="0.00 0.00 0.00" xyz="0.00 0.00 0.00"/>
            </collision>
        </link>
        <link name="rv5as_shoulder">
            <visual>
                <material name="white"/>
                <geometry>
                    <mesh filename="package://melfa_description/meshes/rv5as/shoulder.STL" />
                </geometry>
                <origin rpy="0.00 0.00 0" xyz="0.00 0.00 0.00"/>
            </visual>
            <collision>
                <geometry>
                    <mesh filename="package://melfa_description/meshes/rv5as/shoulder.STL" />
                </geometry>
                <origin rpy="0.00 0.00 0" xyz="0.00 0.00 0.00"/>
            </collision>
        </link>
        <link name="rv5as_upper_arm">
            <visual>
                <material name="white"/>
                <geometry>
                    <mesh filename="package://melfa_description/meshes/rv5as/upper_arm.STL" />
                </geometry>
                <origin rpy="0.00 0.00 0.00" xyz="0.00 0.00 0.00"/>
            </visual>
            <collision>
                <geometry>
                    <mesh filename="package://melfa_description/meshes/rv5as/upper_arm.STL" />
                </geometry>
                <origin rpy="0.00 0.00 0.00" xyz="0.00 0.00 0.00"/>
            </collision>
        </link>
        <link name="rv5as_wrist">
            <visual>
                <material name="white"/>
                <geometry>
                    <mesh filename="package://melfa_description/meshes/rv5as/wrist.STL" />
                </geometry>
                <origin rpy="0.00 0.00 0.00" xyz="0.00 0.00 0.00"/>
            </visual>
            <collision>
                <geometry>
                    <mesh filename="package://melfa_description/meshes/rv5as/wrist.STL" />
                </geometry>
                <origin rpy="0.00 0.00 0.00" xyz="0.00 0.00 0.00"/>
            </collision>
        </link>
    </xacro:macro>
</robot>